[2024-02-12T13:37:17.885+0000] {scheduler_job_runner.py:1586} WARNING - Marking task instance <TaskInstance: consumer_dag.aur_103_erp_ledger_voucher scheduled__2024-02-11T00:00:00+00:00 [queued]> stuck in queued as failed. If the task instance has available retries, it will be retried.
[2024-02-12T13:37:17.934+0000] {scheduler_job_runner.py:781} ERROR - Executor reports task instance <TaskInstance: consumer_dag.aur_103_erp_ledger_voucher scheduled__2024-02-11T00:00:00+00:00 [queued]> finished (failed) although the task says it's queued. (Info: None) Was the task killed externally?
