[2024-02-12T14:06:51.869+0000] {taskinstance.py:1956} INFO - Dependencies all met for dep_context=non-requeueable deps ti=<TaskInstance: kafka.consumer_task scheduled__2024-02-11T00:00:00+00:00 [queued]>
[2024-02-12T14:06:51.884+0000] {taskinstance.py:1956} INFO - Dependencies all met for dep_context=requeueable deps ti=<TaskInstance: kafka.consumer_task scheduled__2024-02-11T00:00:00+00:00 [queued]>
[2024-02-12T14:06:51.885+0000] {taskinstance.py:2170} INFO - Starting attempt 1 of 1
[2024-02-12T14:06:51.907+0000] {taskinstance.py:2191} INFO - Executing <Task(PythonOperator): consumer_task> on 2024-02-11 00:00:00+00:00
[2024-02-12T14:06:51.915+0000] {standard_task_runner.py:60} INFO - Started process 70 to run task
[2024-02-12T14:06:51.922+0000] {standard_task_runner.py:87} INFO - Running: ['***', 'tasks', 'run', 'kafka', 'consumer_task', 'scheduled__2024-02-11T00:00:00+00:00', '--job-id', '3', '--raw', '--subdir', 'DAGS_FOLDER/consumer_dag.py', '--cfg-path', '/tmp/tmpm4gv_fcz']
[2024-02-12T14:06:51.928+0000] {standard_task_runner.py:88} INFO - Job 3: Subtask consumer_task
[2024-02-12T14:06:52.010+0000] {task_command.py:423} INFO - Running <TaskInstance: kafka.consumer_task scheduled__2024-02-11T00:00:00+00:00 [running]> on host 6877a0c67601
[2024-02-12T14:06:52.260+0000] {taskinstance.py:2480} INFO - Exporting env vars: AIRFLOW_CTX_DAG_OWNER='***' AIRFLOW_CTX_DAG_ID='kafka' AIRFLOW_CTX_TASK_ID='consumer_task' AIRFLOW_CTX_EXECUTION_DATE='2024-02-11T00:00:00+00:00' AIRFLOW_CTX_TRY_NUMBER='1' AIRFLOW_CTX_DAG_RUN_ID='scheduled__2024-02-11T00:00:00+00:00'
[2024-02-12T14:06:52.269+0000] {taskinstance.py:2698} ERROR - Task failed with exception
Traceback (most recent call last):
  File "/home/airflow/.local/lib/python3.8/site-packages/airflow/models/taskinstance.py", line 433, in _execute_task
    result = execute_callable(context=context, **execute_callable_kwargs)
  File "/home/airflow/.local/lib/python3.8/site-packages/airflow/operators/python.py", line 199, in execute
    return_value = self.execute_callable()
  File "/home/airflow/.local/lib/python3.8/site-packages/airflow/operators/python.py", line 216, in execute_callable
    return self.python_callable(*self.op_args, **self.op_kwargs)
  File "/opt/airflow/dags/baserow_add_data.py", line 26, in main
    with open("./data/vgsales.csv", "r", newline='', encoding='utf-8') as csv_file:
FileNotFoundError: [Errno 2] No such file or directory: './data/vgsales.csv'
[2024-02-12T14:06:52.300+0000] {taskinstance.py:1138} INFO - Marking task as FAILED. dag_id=kafka, task_id=consumer_task, execution_date=20240211T000000, start_date=20240212T140651, end_date=20240212T140652
[2024-02-12T14:06:52.338+0000] {standard_task_runner.py:107} ERROR - Failed to execute job 3 for task consumer_task ([Errno 2] No such file or directory: './data/vgsales.csv'; 70)
[2024-02-12T14:06:52.376+0000] {local_task_job_runner.py:234} INFO - Task exited with return code 1
[2024-02-12T14:06:52.431+0000] {taskinstance.py:3280} INFO - 0 downstream tasks scheduled from follow-on schedule check
