[2024-02-13T12:12:32.903+0000] {taskinstance.py:1956} INFO - Dependencies all met for dep_context=non-requeueable deps ti=<TaskInstance: baserowdata.consumer_task scheduled__2024-02-12T01:30:00+00:00 [queued]>
[2024-02-13T12:12:32.938+0000] {taskinstance.py:1956} INFO - Dependencies all met for dep_context=requeueable deps ti=<TaskInstance: baserowdata.consumer_task scheduled__2024-02-12T01:30:00+00:00 [queued]>
[2024-02-13T12:12:32.939+0000] {taskinstance.py:2170} INFO - Starting attempt 1 of 1
[2024-02-13T12:12:33.004+0000] {taskinstance.py:2191} INFO - Executing <Task(PythonOperator): consumer_task> on 2024-02-12 01:30:00+00:00
[2024-02-13T12:12:33.037+0000] {standard_task_runner.py:60} INFO - Started process 120 to run task
[2024-02-13T12:12:33.049+0000] {standard_task_runner.py:87} INFO - Running: ['***', 'tasks', 'run', 'baserowdata', 'consumer_task', 'scheduled__2024-02-12T01:30:00+00:00', '--job-id', '20', '--raw', '--subdir', 'DAGS_FOLDER/consumer_dag.py', '--cfg-path', '/tmp/tmpwu80jupa']
[2024-02-13T12:12:33.054+0000] {standard_task_runner.py:88} INFO - Job 20: Subtask consumer_task
[2024-02-13T12:12:33.229+0000] {task_command.py:423} INFO - Running <TaskInstance: baserowdata.consumer_task scheduled__2024-02-12T01:30:00+00:00 [running]> on host b9c9154d9bc2
[2024-02-13T12:12:33.637+0000] {taskinstance.py:2480} INFO - Exporting env vars: AIRFLOW_CTX_DAG_OWNER='***' AIRFLOW_CTX_DAG_ID='baserowdata' AIRFLOW_CTX_TASK_ID='consumer_task' AIRFLOW_CTX_EXECUTION_DATE='2024-02-12T01:30:00+00:00' AIRFLOW_CTX_TRY_NUMBER='1' AIRFLOW_CTX_DAG_RUN_ID='scheduled__2024-02-12T01:30:00+00:00'
[2024-02-13T12:12:34.424+0000] {logging_mixin.py:188} INFO - İstek başarılı.
[2024-02-13T12:12:35.334+0000] {logging_mixin.py:188} INFO - İstek başarılı.
[2024-02-13T12:12:35.890+0000] {logging_mixin.py:188} INFO - İstek başarılı.
[2024-02-13T12:12:36.435+0000] {logging_mixin.py:188} INFO - İstek başarılı.
[2024-02-13T12:12:37.262+0000] {logging_mixin.py:188} INFO - İstek başarılı.
[2024-02-13T12:12:37.888+0000] {logging_mixin.py:188} INFO - İstek başarılı.
[2024-02-13T12:12:38.485+0000] {logging_mixin.py:188} INFO - İstek başarılı.
[2024-02-13T12:12:39.219+0000] {logging_mixin.py:188} INFO - İstek başarılı.
[2024-02-13T12:12:39.951+0000] {logging_mixin.py:188} INFO - İstek başarılı.
[2024-02-13T12:12:40.911+0000] {logging_mixin.py:188} INFO - İstek başarılı.
[2024-02-13T12:12:41.560+0000] {logging_mixin.py:188} INFO - İstek başarılı.
[2024-02-13T12:12:42.196+0000] {logging_mixin.py:188} INFO - İstek başarılı.
[2024-02-13T12:12:42.841+0000] {logging_mixin.py:188} INFO - İstek başarılı.
[2024-02-13T12:12:43.431+0000] {logging_mixin.py:188} INFO - İstek başarılı.
[2024-02-13T12:12:44.008+0000] {logging_mixin.py:188} INFO - İstek başarılı.
[2024-02-13T12:12:44.639+0000] {logging_mixin.py:188} INFO - İstek başarılı.
[2024-02-13T12:12:45.143+0000] {logging_mixin.py:188} INFO - İstek başarılı.
[2024-02-13T12:12:45.747+0000] {logging_mixin.py:188} INFO - İstek başarılı.
[2024-02-13T12:12:46.319+0000] {logging_mixin.py:188} INFO - İstek başarılı.
[2024-02-13T12:12:46.945+0000] {logging_mixin.py:188} INFO - İstek başarılı.
[2024-02-13T12:12:47.487+0000] {logging_mixin.py:188} INFO - İstek başarılı.
[2024-02-13T12:12:48.256+0000] {logging_mixin.py:188} INFO - İstek başarılı.
[2024-02-13T12:12:48.858+0000] {logging_mixin.py:188} INFO - İstek başarılı.
[2024-02-13T12:12:48.867+0000] {taskinstance.py:2698} ERROR - Task failed with exception
Traceback (most recent call last):
  File "/home/airflow/.local/lib/python3.8/site-packages/airflow/models/taskinstance.py", line 433, in _execute_task
    result = execute_callable(context=context, **execute_callable_kwargs)
  File "/home/airflow/.local/lib/python3.8/site-packages/airflow/operators/python.py", line 199, in execute
    return_value = self.execute_callable()
  File "/home/airflow/.local/lib/python3.8/site-packages/airflow/operators/python.py", line 216, in execute_callable
    return self.python_callable(*self.op_args, **self.op_kwargs)
  File "/opt/airflow/dags/consumer_dag.py", line 66, in main
    writer.writerows(rows)
  File "/usr/local/lib/python3.8/csv.py", line 157, in writerows
    return self.writer.writerows(map(self._dict_to_list, rowdicts))
  File "/usr/local/lib/python3.8/csv.py", line 149, in _dict_to_list
    raise ValueError("dict contains fields not in fieldnames: "
ValueError: dict contains fields not in fieldnames: None
[2024-02-13T12:12:48.921+0000] {taskinstance.py:1138} INFO - Marking task as FAILED. dag_id=baserowdata, task_id=consumer_task, execution_date=20240212T013000, start_date=20240213T121232, end_date=20240213T121248
[2024-02-13T12:12:49.170+0000] {standard_task_runner.py:107} ERROR - Failed to execute job 20 for task consumer_task (dict contains fields not in fieldnames: None; 120)
[2024-02-13T12:12:49.203+0000] {local_task_job_runner.py:234} INFO - Task exited with return code 1
[2024-02-13T12:12:49.240+0000] {taskinstance.py:3280} INFO - 0 downstream tasks scheduled from follow-on schedule check
